Traceback (most recent call last):
  File "c:\python39\lib\site-packages\jupyter_cache\executors\utils.py", line 58, in single_nb_execution
    executenb(
  File "c:\python39\lib\site-packages\nbclient\client.py", line 1305, in execute
    return NotebookClient(nb=nb, resources=resources, km=km, **kwargs).execute()
  File "C:\Users\matth\AppData\Roaming\Python\Python39\site-packages\jupyter_core\utils\__init__.py", line 166, in wrapped
    return loop.run_until_complete(inner)
  File "c:\python39\lib\asyncio\base_events.py", line 642, in run_until_complete
    return future.result()
  File "c:\python39\lib\site-packages\nbclient\client.py", line 705, in async_execute
    await self.async_execute_cell(
  File "c:\python39\lib\site-packages\nbclient\client.py", line 1058, in async_execute_cell
    await self._check_raise_for_error(cell, cell_index, exec_reply)
  File "c:\python39\lib\site-packages\nbclient\client.py", line 914, in _check_raise_for_error
    raise CellExecutionError.from_cell_and_msg(cell, exec_reply_content)
nbclient.exceptions.CellExecutionError: An error occurred while executing the following cell:
------------------
# Load pretrained Faster R-CNN model
model = torchvision.models.detection.fasterrcnn_resnet50_fpn(pretrained=True, min_size=800)

# This model is trained to detect the following classes
coco_names = [
    '__background__', 'person', 'bicycle', 'car', 'motorcycle', 'airplane', 'bus',
    'train', 'truck', 'boat', 'traffic light', 'fire hydrant', 'N/A', 'stop sign',
    'parking meter', 'bench', 'bird', 'cat', 'dog', 'horse', 'sheep', 'cow',
    'elephant', 'bear', 'zebra', 'giraffe', 'N/A', 'backpack', 'umbrella', 'N/A', 'N/A',
    'handbag', 'tie', 'suitcase', 'frisbee', 'skis', 'snowboard', 'sports ball',
    'kite', 'baseball bat', 'baseball glove', 'skateboard', 'surfboard', 'tennis racket',
    'bottle', 'N/A', 'wine glass', 'cup', 'fork', 'knife', 'spoon', 'bowl',
    'banana', 'apple', 'sandwich', 'orange', 'broccoli', 'carrot', 'hot dog', 'pizza',
    'donut', 'cake', 'chair', 'couch', 'potted plant', 'bed', 'N/A', 'dining table',
    'N/A', 'N/A', 'toilet', 'N/A', 'tv', 'laptop', 'mouse', 'remote', 'keyboard', 'cell phone',
    'microwave', 'oven', 'toaster', 'sink', 'refrigerator', 'N/A', 'book',
    'clock', 'vase', 'scissors', 'teddy bear', 'hair drier', 'toothbrush'
]
------------------

----- stdout -----
Unexpected exception formatting exception. Falling back to standard exception
----- stderr -----
Traceback (most recent call last):
  File "C:\Users\matth\AppData\Roaming\Python\Python39\site-packages\IPython\core\interactiveshell.py", line 3442, in run_code
    exec(code_obj, self.user_global_ns, self.user_ns)
  File "C:\Users\matth\AppData\Local\Temp\ipykernel_1128\3814406358.py", line 2, in <module>
    model = torchvision.models.detection.fasterrcnn_resnet50_fpn(pretrained=True, min_size=800)
  File "c:\python39\lib\site-packages\torchvision\models\detection\faster_rcnn.py", line 394, in fasterrcnn_resnet50_fpn
    backbone = resnet50(pretrained=pretrained_backbone, progress=progress, norm_layer=misc_nn_ops.FrozenBatchNorm2d)
  File "c:\python39\lib\site-packages\torchvision\models\resnet.py", line 331, in resnet50
    return _resnet("resnet50", Bottleneck, [3, 4, 6, 3], pretrained, progress, **kwargs)
  File "c:\python39\lib\site-packages\torchvision\models\resnet.py", line 294, in _resnet
    model = ResNet(block, layers, **kwargs)
  File "c:\python39\lib\site-packages\torchvision\models\resnet.py", line 202, in __init__
    self.layer4 = self._make_layer(block, 512, layers[3], stride=2, dilate=replace_stride_with_dilation[2])
  File "c:\python39\lib\site-packages\torchvision\models\resnet.py", line 252, in _make_layer
    block(
  File "c:\python39\lib\site-packages\torchvision\models\resnet.py", line 135, in __init__
    self.conv3 = conv1x1(width, planes * self.expansion)
  File "c:\python39\lib\site-packages\torchvision\models\resnet.py", line 54, in conv1x1
    return nn.Conv2d(in_planes, out_planes, kernel_size=1, stride=stride, bias=False)
  File "c:\python39\lib\site-packages\torch\nn\modules\conv.py", line 434, in __init__
    super(Conv2d, self).__init__(
  File "c:\python39\lib\site-packages\torch\nn\modules\conv.py", line 131, in __init__
    self.weight = Parameter(torch.empty(
RuntimeError: [enforce fail at C:\actions-runner\_work\pytorch\pytorch\builder\windows\pytorch\c10\core\impl\alloc_cpu.cpp:81] data. DefaultCPUAllocator: not enough memory: you tried to allocate 4194304 bytes.

During handling of the above exception, another exception occurred:

Traceback (most recent call last):
  File "C:\Users\matth\AppData\Roaming\Python\Python39\site-packages\IPython\core\interactiveshell.py", line 2057, in showtraceback
    stb = self.InteractiveTB.structured_traceback(
  File "C:\Users\matth\AppData\Roaming\Python\Python39\site-packages\IPython\core\ultratb.py", line 1118, in structured_traceback
    return FormattedTB.structured_traceback(
  File "C:\Users\matth\AppData\Roaming\Python\Python39\site-packages\IPython\core\ultratb.py", line 1012, in structured_traceback
    return VerboseTB.structured_traceback(
  File "C:\Users\matth\AppData\Roaming\Python\Python39\site-packages\IPython\core\ultratb.py", line 865, in structured_traceback
    formatted_exception = self.format_exception_as_a_whole(etype, evalue, etb, number_of_lines_of_context,
  File "C:\Users\matth\AppData\Roaming\Python\Python39\site-packages\IPython\core\ultratb.py", line 799, in format_exception_as_a_whole
    self.get_records(etb, number_of_lines_of_context, tb_offset) if etb else []
  File "C:\Users\matth\AppData\Roaming\Python\Python39\site-packages\IPython\core\ultratb.py", line 854, in get_records
    return list(stack_data.FrameInfo.stack_data(etb, options=options))[tb_offset:]
  File "C:\Users\matth\AppData\Roaming\Python\Python39\site-packages\stack_data\core.py", line 597, in stack_data
    yield from collapse_repeated(
  File "C:\Users\matth\AppData\Roaming\Python\Python39\site-packages\stack_data\utils.py", line 83, in collapse_repeated
    yield from map(mapper, original_group)
  File "C:\Users\matth\AppData\Roaming\Python\Python39\site-packages\stack_data\core.py", line 587, in mapper
    return cls(f, options)
  File "C:\Users\matth\AppData\Roaming\Python\Python39\site-packages\stack_data\core.py", line 551, in __init__
    self.executing = Source.executing(frame_or_tb)
  File "C:\Users\matth\AppData\Roaming\Python\Python39\site-packages\executing\executing.py", line 359, in executing
    source = cls.for_frame(frame)
  File "C:\Users\matth\AppData\Roaming\Python\Python39\site-packages\executing\executing.py", line 277, in for_frame
    return cls.for_filename(frame.f_code.co_filename, frame.f_globals or {}, use_cache)
  File "C:\Users\matth\AppData\Roaming\Python\Python39\site-packages\executing\executing.py", line 306, in for_filename
    return cls._for_filename_and_lines(filename, tuple(lines))
  File "C:\Users\matth\AppData\Roaming\Python\Python39\site-packages\executing\executing.py", line 317, in _for_filename_and_lines
    result = source_cache[(filename, lines)] = cls(filename, lines)
  File "C:\Users\matth\AppData\Roaming\Python\Python39\site-packages\executing\executing.py", line 257, in __init__
    self.tree = ast.parse(ast_text, filename=filename)
  File "c:\python39\lib\ast.py", line 50, in parse
    return compile(source, filename, mode, flags,
SystemError: <built-in function compile> returned NULL without setting an error
------------------



