Traceback (most recent call last):
  File "C:\Python310\lib\site-packages\jupyter_cache\executors\utils.py", line 58, in single_nb_execution
    executenb(
  File "C:\Users\matth\AppData\Roaming\Python\Python310\site-packages\nbclient\client.py", line 1314, in execute
    return NotebookClient(nb=nb, resources=resources, km=km, **kwargs).execute()
  File "C:\Users\matth\AppData\Roaming\Python\Python310\site-packages\jupyter_core\utils\__init__.py", line 173, in wrapped
    return loop.run_until_complete(inner)
  File "C:\Python310\lib\asyncio\base_events.py", line 649, in run_until_complete
    return future.result()
  File "C:\Users\matth\AppData\Roaming\Python\Python310\site-packages\nbclient\client.py", line 709, in async_execute
    await self.async_execute_cell(
  File "C:\Users\matth\AppData\Roaming\Python\Python310\site-packages\nbclient\client.py", line 1062, in async_execute_cell
    await self._check_raise_for_error(cell, cell_index, exec_reply)
  File "C:\Users\matth\AppData\Roaming\Python\Python310\site-packages\nbclient\client.py", line 918, in _check_raise_for_error
    raise CellExecutionError.from_cell_and_msg(cell, exec_reply_content)
nbclient.exceptions.CellExecutionError: An error occurred while executing the following cell:
------------------
# Imports
import cv2
import imutils
import numpy as np
from imutils import contours
from imutils import perspective
from scipy.spatial import distance as dist
import matplotlib.pyplot as plt
------------------


[1;31m---------------------------------------------------------------------------[0m
[1;31mAttributeError[0m                            Traceback (most recent call last)
Cell [1;32mIn[1], line 3[0m
[0;32m      1[0m [38;5;66;03m# Imports[39;00m
[0;32m      2[0m [38;5;28;01mimport[39;00m [38;5;21;01mcv2[39;00m
[1;32m----> 3[0m [38;5;28;01mimport[39;00m [38;5;21;01mimutils[39;00m
[0;32m      4[0m [38;5;28;01mimport[39;00m [38;5;21;01mnumpy[39;00m [38;5;28;01mas[39;00m [38;5;21;01mnp[39;00m
[0;32m      5[0m [38;5;28;01mfrom[39;00m [38;5;21;01mimutils[39;00m [38;5;28;01mimport[39;00m contours

File [1;32mC:\Python310\lib\site-packages\imutils\__init__.py:8[0m
[0;32m      5[0m __version__ [38;5;241m=[39m [38;5;124m"[39m[38;5;124m0.5.4[39m[38;5;124m"[39m
[0;32m      7[0m [38;5;66;03m# import the necessary packages[39;00m
[1;32m----> 8[0m [38;5;28;01mfrom[39;00m [38;5;21;01m.[39;00m[38;5;21;01mconvenience[39;00m [38;5;28;01mimport[39;00m translate
[0;32m      9[0m [38;5;28;01mfrom[39;00m [38;5;21;01m.[39;00m[38;5;21;01mconvenience[39;00m [38;5;28;01mimport[39;00m rotate
[0;32m     10[0m [38;5;28;01mfrom[39;00m [38;5;21;01m.[39;00m[38;5;21;01mconvenience[39;00m [38;5;28;01mimport[39;00m rotate_bound

File [1;32mC:\Python310\lib\site-packages\imutils\convenience.py:65[0m
[0;32m     62[0m     [38;5;66;03m# perform the actual rotation and return the image[39;00m
[0;32m     63[0m     [38;5;28;01mreturn[39;00m cv2[38;5;241m.[39mwarpAffine(image, M, (nW, nH))
[1;32m---> 65[0m [38;5;28;01mdef[39;00m [38;5;21mresize[39m(image, width[38;5;241m=[39m[38;5;28;01mNone[39;00m, height[38;5;241m=[39m[38;5;28;01mNone[39;00m, inter[38;5;241m=[39m[43mcv2[49m[38;5;241;43m.[39;49m[43mINTER_AREA[49m):
[0;32m     66[0m     [38;5;66;03m# initialize the dimensions of the image to be resized and[39;00m
[0;32m     67[0m     [38;5;66;03m# grab the image size[39;00m
[0;32m     68[0m     dim [38;5;241m=[39m [38;5;28;01mNone[39;00m
[0;32m     69[0m     (h, w) [38;5;241m=[39m image[38;5;241m.[39mshape[:[38;5;241m2[39m]

[1;31mAttributeError[0m: module 'cv2' has no attribute 'INTER_AREA'

