Traceback (most recent call last):
  File "c:\python39\lib\site-packages\jupyter_cache\executors\utils.py", line 58, in single_nb_execution
    executenb(
  File "c:\python39\lib\site-packages\nbclient\client.py", line 1305, in execute
    return NotebookClient(nb=nb, resources=resources, km=km, **kwargs).execute()
  File "C:\Users\matth\AppData\Roaming\Python\Python39\site-packages\jupyter_core\utils\__init__.py", line 166, in wrapped
    return loop.run_until_complete(inner)
  File "c:\python39\lib\asyncio\base_events.py", line 642, in run_until_complete
    return future.result()
  File "c:\python39\lib\site-packages\nbclient\client.py", line 705, in async_execute
    await self.async_execute_cell(
  File "c:\python39\lib\site-packages\nbclient\client.py", line 1058, in async_execute_cell
    await self._check_raise_for_error(cell, cell_index, exec_reply)
  File "c:\python39\lib\site-packages\nbclient\client.py", line 914, in _check_raise_for_error
    raise CellExecutionError.from_cell_and_msg(cell, exec_reply_content)
nbclient.exceptions.CellExecutionError: An error occurred while executing the following cell:
------------------
# Add image two to the previous created frame to obtain the stiched image
dst[0:img2.shape[0], 0:img2.shape[1]] = image2 

# Show image
plt.imshow(dst)
plt.show()
------------------


[1;31m---------------------------------------------------------------------------[0m
[1;31mNameError[0m                                 Traceback (most recent call last)
Cell [1;32mIn[7], line 2[0m
[0;32m      1[0m [38;5;66;03m# Add image two to the previous created frame to obtain the stiched image[39;00m
[1;32m----> 2[0m dst[[38;5;241m0[39m:[43mimg2[49m[38;5;241m.[39mshape[[38;5;241m0[39m], [38;5;241m0[39m:img2[38;5;241m.[39mshape[[38;5;241m1[39m]] [38;5;241m=[39m image2 
[0;32m      4[0m [38;5;66;03m# Show image[39;00m
[0;32m      5[0m plt[38;5;241m.[39mimshow(dst)

[1;31mNameError[0m: name 'img2' is not defined

