Traceback (most recent call last):
  File "c:\python39\lib\site-packages\jupyter_cache\executors\utils.py", line 58, in single_nb_execution
    executenb(
  File "c:\python39\lib\site-packages\nbclient\client.py", line 1305, in execute
    return NotebookClient(nb=nb, resources=resources, km=km, **kwargs).execute()
  File "C:\Users\matth\AppData\Roaming\Python\Python39\site-packages\jupyter_core\utils\__init__.py", line 166, in wrapped
    return loop.run_until_complete(inner)
  File "c:\python39\lib\asyncio\base_events.py", line 642, in run_until_complete
    return future.result()
  File "c:\python39\lib\site-packages\nbclient\client.py", line 705, in async_execute
    await self.async_execute_cell(
  File "c:\python39\lib\site-packages\nbclient\client.py", line 1058, in async_execute_cell
    await self._check_raise_for_error(cell, cell_index, exec_reply)
  File "c:\python39\lib\site-packages\nbclient\client.py", line 914, in _check_raise_for_error
    raise CellExecutionError.from_cell_and_msg(cell, exec_reply_content)
nbclient.exceptions.CellExecutionError: An error occurred while executing the following cell:
------------------
# Grayscale Transform
b, g, r = cv2.split(image)
gray = 2 * g - r - b
------------------


[1;31m---------------------------------------------------------------------------[0m
[1;31mValueError[0m                                Traceback (most recent call last)
Cell [1;32mIn[3], line 2[0m
[0;32m      1[0m [38;5;66;03m# Grayscale Transform[39;00m
[1;32m----> 2[0m b, g, r [38;5;241m=[39m cv2[38;5;241m.[39msplit(image)
[0;32m      3[0m gray [38;5;241m=[39m [38;5;241m2[39m [38;5;241m*[39m g [38;5;241m-[39m r [38;5;241m-[39m b

[1;31mValueError[0m: not enough values to unpack (expected 3, got 0)

