Traceback (most recent call last):
  File "c:\python39\lib\site-packages\myst_nb\core\execute\inline.py", line 127, in code_cell_outputs
    self._client.execute_cell(
  File "C:\Users\matth\AppData\Roaming\Python\Python39\site-packages\jupyter_core\utils\__init__.py", line 166, in wrapped
    return loop.run_until_complete(inner)
  File "c:\python39\lib\asyncio\base_events.py", line 642, in run_until_complete
    return future.result()
  File "c:\python39\lib\site-packages\nbclient\client.py", line 1058, in async_execute_cell
    await self._check_raise_for_error(cell, cell_index, exec_reply)
  File "c:\python39\lib\site-packages\nbclient\client.py", line 914, in _check_raise_for_error
    raise CellExecutionError.from_cell_and_msg(cell, exec_reply_content)
nbclient.exceptions.CellExecutionError: An error occurred while executing the following cell:
------------------
# Use dataset
dataset = CustomDataset()
data_loader = DataLoader(dataset, batch_size=4, shuffle=True)
for imgs, labels in data_loader:
    print("Batch of images has shape: ", imgs.shape)
    print("Batch of labels has shape: ", labels.shape)
------------------


[1;31m---------------------------------------------------------------------------[0m
[1;31mValueError[0m                                Traceback (most recent call last)
Cell [1;32mIn[3], line 3[0m
[0;32m      1[0m [38;5;66;03m# Use dataset[39;00m
[0;32m      2[0m dataset [38;5;241m=[39m CustomDataset()
[1;32m----> 3[0m data_loader [38;5;241m=[39m [43mDataLoader[49m[43m([49m[43mdataset[49m[43m,[49m[43m [49m[43mbatch_size[49m[38;5;241;43m=[39;49m[38;5;241;43m4[39;49m[43m,[49m[43m [49m[43mshuffle[49m[38;5;241;43m=[39;49m[38;5;28;43;01mTrue[39;49;00m[43m)[49m
[0;32m      4[0m [38;5;28;01mfor[39;00m imgs, labels [38;5;129;01min[39;00m data_loader:
[0;32m      5[0m     [38;5;28mprint[39m([38;5;124m"[39m[38;5;124mBatch of images has shape: [39m[38;5;124m"[39m, imgs[38;5;241m.[39mshape)

File [1;32mc:\python39\lib\site-packages\torch\utils\data\dataloader.py:277[0m, in [0;36mDataLoader.__init__[1;34m(self, dataset, batch_size, shuffle, sampler, batch_sampler, num_workers, collate_fn, pin_memory, drop_last, timeout, worker_init_fn, multiprocessing_context, generator, prefetch_factor, persistent_workers)[0m
[0;32m    275[0m [38;5;28;01melse[39;00m:  [38;5;66;03m# map-style[39;00m
[0;32m    276[0m     [38;5;28;01mif[39;00m shuffle:
[1;32m--> 277[0m         sampler [38;5;241m=[39m [43mRandomSampler[49m[43m([49m[43mdataset[49m[43m,[49m[43m [49m[43mgenerator[49m[38;5;241;43m=[39;49m[43mgenerator[49m[43m)[49m  [38;5;66;03m# type: ignore[arg-type][39;00m
[0;32m    278[0m     [38;5;28;01melse[39;00m:
[0;32m    279[0m         sampler [38;5;241m=[39m SequentialSampler(dataset)  [38;5;66;03m# type: ignore[arg-type][39;00m

File [1;32mc:\python39\lib\site-packages\torch\utils\data\sampler.py:97[0m, in [0;36mRandomSampler.__init__[1;34m(self, data_source, replacement, num_samples, generator)[0m
[0;32m     93[0m     [38;5;28;01mraise[39;00m [38;5;167;01mTypeError[39;00m([38;5;124m"[39m[38;5;124mreplacement should be a boolean value, but got [39m[38;5;124m"[39m
[0;32m     94[0m                     [38;5;124m"[39m[38;5;124mreplacement=[39m[38;5;132;01m{}[39;00m[38;5;124m"[39m[38;5;241m.[39mformat([38;5;28mself[39m[38;5;241m.[39mreplacement))
[0;32m     96[0m [38;5;28;01mif[39;00m [38;5;129;01mnot[39;00m [38;5;28misinstance[39m([38;5;28mself[39m[38;5;241m.[39mnum_samples, [38;5;28mint[39m) [38;5;129;01mor[39;00m [38;5;28mself[39m[38;5;241m.[39mnum_samples [38;5;241m<[39m[38;5;241m=[39m [38;5;241m0[39m:
[1;32m---> 97[0m     [38;5;28;01mraise[39;00m [38;5;167;01mValueError[39;00m([38;5;124m"[39m[38;5;124mnum_samples should be a positive integer [39m[38;5;124m"[39m
[0;32m     98[0m                      [38;5;124m"[39m[38;5;124mvalue, but got num_samples=[39m[38;5;132;01m{}[39;00m[38;5;124m"[39m[38;5;241m.[39mformat([38;5;28mself[39m[38;5;241m.[39mnum_samples))

[1;31mValueError[0m: num_samples should be a positive integer value, but got num_samples=0

